Workbook
Name Slicer_Subsidiary: #N/A

Sheet Sheet3
G14: Marzo
A15: Abril | G15: Row Labels | H15: Sum of Amount Remaining
A16: Row Labels | B16: Sum of Amount Remaining | G16: Americas | H16: 1964139.4 | J16: =GETPIVOTDATA("Amount Remaining",$A$16,"Subsidiary","Americas")-H16 -> -835002.12
A17: Americas | B17: 1129137.3 | G17: APAC | H17: 4210.652
A18: APAC | B18: 225886.59 | G18: EMEA | H18: 37757.611
A19: EMEA | B19: 1560344.9 | G19: Sysomos | H19: 313476.89
A20: Grand Total | B20: 2915368.8 | G20: Grand Total | H20: 4792721.2
F28: By Region/YR
F29: Sum of Amount Remaining
F30: 1129137.3

Sheet Sheet4
A12: Row Labels | B12: Sum of Amount Remaining | E12: Row Labels | F12: Sum of Amount Remaining
A13: Americas | B13: 1129137.3 | E13: Americas | F13: 1129137.3
A14: APAC | B14: 225886.59 | E14: APAC | F14: 225886.59
A15: EMEA | B15: 1558558.2 | E15: EMEA | F15: 1558558.2
A16: Grand Total | B16: 2913582.1 | E16: Grand Total | F16: 2913582.1
A20: By Region/YR
A22: SUBSIDIARY | B22: Americas | E22: SUBSIDIARY | F22: APAC | H22: SUBSIDIARY | I22: EMEA
A24: Row Labels | B24: Sum of Amount Remaining | E24: Row Labels | F24: Sum of Amount Remaining | H24: Row Labels | I24: Sum of Amount Remaining
A25: 2022 | B25: 247647.77 | E25: 2022 | F25: 6331.471 | H25: 2022 | I25: 136434.15
A26: 2023 | B26: 161269.48 | E26: 2023 | F26: 118148.64 | H26: 2023 | I26: 320347.94
A27: 2024 | B27: 47448.118 | E27: 2024 | F27: 20152.823 | H27: 2024 | I27: 219682.33
A28: 2025 | B28: 369312.24 | E28: 2025 | F28: 25616.49 | H28: 2025 | I28: 341332.87
A29: 2026 | B29: 303459.69 | E29: 2026 | F29: 55637.166 | H29: 2026 | I29: 541621.09
A30: Grand Total | B30: 1129137.3 | E30: Grand Total | F30: 225886.59 | H30: Grand Total | I30: 1559418.4

Sheet UnappliedPaymentsErnestoResult
A1: Subsidiary (no hierarchy) | B1: Date | C1: MES | D1: AÑO | E1: SUBSIDIARY | F1: Status | G1: Number | H1: Invoice Number | I1: Currency | J1: Amount Base | K1: Amount USD | L1: Amount Remaining | M1: Balance | N1: Customer Name | O1: AR Specialist | P1: Memo
A2: 102 - US | B2: 45736 | C2: =UPPER(TEXT(B2, "[$-en-US]mmmm")) -> MARCH | D2: =YEAR(B2) -> 2025 | E2: =VLOOKUP(A2,Sheet2!A:B,2,0) -> Americas | F2: Deposited | G2: PMT-S151-202999 | I2: USD | J2: -81229.11 | K2: -81229.11 | L2: 81229.11 | M2: -250567.82 | N2: DUMMY CUSTOMER_CASHAPPS 102 - US | P2: ACH CONCENTRATION CREDIT ACH CORP TRADE PAYMENT FROM MICROSOFT MICROSOFT 0004992933 68251185441010
A3: 102 - US | B3: 45922 | C3: =UPPER(TEXT(B3, "[$-en-US]mmmm")) -> SEPTEMBER | D3: =YEAR(B3) -> 2025 | E3: =VLOOKUP(A3,Sheet2!A:B,2,0) -> Americas | F3: Deposited | G3: PMT-S151-211138 | I3: USD | J3: -54445.55 | K3: -54445.55 | L3: 54445.55 | M3: -50095.55 | N3: Microsoft Corporation | P3: ACH CONCENTRATION CREDIT ACH CORP TRADE PAYMENT FROM MICROSOFT MICROSOFT 0005317824 68550845931010
A4: 102 - US | B4: 46071 | C4: =UPPER(TEXT(B4, "[$-en-US]mmmm")) -> FEBRUARY | D4: =YEAR(B4) -> 2026 | E4: =VLOOKUP(A4,Sheet2!A:B,2,0) -> Americas | F4: Deposited | G4: PMT-S151-219775 | I4: USD | J4: -35534 | K4: -35534 | L4: 35534 | M4: -35534 | N4: Brick Media | P4: INCOMING MONEY TRANSFER 53RECD FED JPMORGAN CHASE BANK*ORG:BRICK MEDIA LLC,RO CKY RIVER OH 44116-1815 US,19885 DETRO*OGB:JPMORGAN CHASE BANK,TAMPA,10410 HI GHLAND MANOR DRIVE*BNF:MELTWATER NEWS US INC,REDWOOD CITY CA/US,275 S HO*STFEDSEQ:B1Q8982R000363*TIME:0341*YOUR REF:WTH OF 26/02/18*OUR REF:0490937 10
A5: 102 - US | B5: 45691 | C5: =UPPER(TEXT(B5, "[$-en-US]mmmm")) -> FEBRUARY | D5: =YEAR(B5) -> 2025 | E5: =VLOOKUP(A5,Sheet2!A:B,2,0) -> Americas | F5: Deposited | G5: PMT-S151-200395 | I5: USD | J5: -32613.85 | K5: -32613.85 | L5: 32613.85 | M5: -250567.82 | N5: DUMMY CUSTOMER_CASHAPPS 102 - US | P5: ACH CONCENTRATION CREDIT ACH CORP TRADE PAYMENT FROM MICROSOFT MICROSOFT 0004890122 68550745441010
A6: 102 - US | B6: 44851 | C6: =UPPER(TEXT(B6, "[$-en-US]mmmm")) -> OCTOBER | D6: =YEAR(B6) -> 2022 | E6: =VLOOKUP(A6,Sheet2!A:B,2,0) -> Americas | F6: Deposited | G6: PMT-S151-156272 | I6: USD | J6: -27218.77 | K6: -27218.77 | L6: 27218.77 | M6: -27218.77 | N6: ComplySci | P6: ACH CONCENTRATION CREDIT ACH CASH CONCENTRATION COMPLYSCI-PAYMENT ComplySci Payment 46810
A7: 102 - US | B7: 45856 | C7: =UPPER(TEXT(B7, "[$-en-US]mmmm")) -> JULY | D7: =YEAR(B7) -> 2025 | E7: =VLOOKUP(A7,Sheet2!A:B,2,0) -> Americas | F7: Deposited | G7: PMT-S151-208003 | I7: USD | J7: -25699.72 | K7: -25699.72 | L7: 25699.72 | M7: -250567.82 | N7: DUMMY CUSTOMER_CASHAPPS 102 - US | P7: ACH CONCENTRATION CREDIT ACH CASH CONCENTRATION ENVIOLOL-PAYMENTS ENVIOLOL PAYMENTS 0000010593
A8: 102 - US | B8: 45838 | C8: =UPPER(TEXT(B8, "[$-en-US]mmmm")) -> JUNE | D8: =YEAR(B8) -> 2025 | E8: =VLOOKUP(A8,Sheet2!A:B,2,0) -> Americas | F8: Deposited | G8: PMT-S151-207105 | I8: USD | J8: -24128 | K8: -24128 | L8: 24128 | M8: -250567.82 | N8: DUMMY CUSTOMER_CASHAPPS 102 - US | P8: ACH CONCENTRATION CREDIT ACH CORP TRADE PAYMENT FROM MICROSOFT MICROSOFT 0005162418 68500854311010
A9: 102 - US | B9: 46118 | C9: =UPPER(TEXT(B9, "[$-en-US]mmmm")) -> APRIL | D9: =YEAR(B9) -> 2026 | E9: =VLOOKUP(A9,Sheet2!A:B,2,0) -> Americas | F9: Deposited | G9: PMT-S151-222326 | I9: USD | J9: -20913.77 | K9: -20913.77 | L9: 20913.77 | M9: -20913.77 | N9: Camp Chef | P9: ACH CONCENTRATION CREDIT ACH CASH CONCENTRATION BUSHNELL OPER-PAYMENT BUSHNELL PAYMENT 2021416
A10: 102 - US | B10: 46127 | C10: =UPPER(TEXT(B10, "[$-en-US]mmmm")) -> APRIL | D10: =YEAR(B10) -> 2026 | E10: =VLOOKUP(A10,Sheet2!A:B,2,0) -> Americas | F10: Deposited | G10: PMT-S151-222780 | I10: USD | J10: -20698 | K10: -20698 | L10: 20698 | M10: -20698 | N10: Culloton + Bauer Luce | P10: ACH CONCENTRATION CREDIT ACH CASH CONCENTRATION CULLOTON STRATEG-ACH PAYMEN Culloton ACH Paymen 95267
A11: 102 - US | B11: 45889 | C11: =UPPER(TEXT(B11, "[$-en-US]mmmm")) -> AUGUST | D11: =YEAR(B11) -> 2025 | E11: =VLOOKUP(A11,Sheet2!A:B,2,0) -> Americas | F11: Deposited | G11: PMT-S151-209700 | I11: USD | J11: -20000 | K11: -20000 | L11: 20000 | M11: -50095.55 | N11: Microsoft Corporation | P11: ACH CONCENTRATION CREDIT ACH CORP TRADE PAYMENT FROM MICROSOFT MICROSOFT 0005263117 68151120631010
A12: 102 - US | B12: 46108 | C12: =UPPER(TEXT(B12, "[$-en-US]mmmm")) -> MARCH | D12: =YEAR(B12) -> 2026 | E12: =VLOOKUP(A12,Sheet2!A:B,2,0) -> Americas | F12: Deposited | G12: PMT-S151-221843 | H12: PMT-S151-221843 | I12: USD | J12: -39600 | K12: -39600 | L12: 19800 | M12: -19800 | N12: Blue Learning | P12: ACH CONCENTRATION CREDIT ACH CASH CONCENTRATION BLUE LEARNING OP-CORP PAY BLUE LEAR CORP PAY 10957
A13: 102 - US | B13: 46139 | C13: =UPPER(TEXT(B13, "[$-en-US]mmmm")) -> APRIL | D13: =YEAR(B13) -> 2026 | E13: =VLOOKUP(A13,Sheet2!A:B,2,0) -> Americas | F13: Deposited | G13: PMT-S151-223322 | I13: USD | J13: -19350 | K13: -19350 | L13: 19350 | M13: -19350 | N13: Gaudenzia, Inc
A14: 102 - US | B14: 45049 | C14: =UPPER(TEXT(B14, "[$-en-US]mmmm")) -> MAY | D14: =YEAR(B14) -> 2023 | E14: =VLOOKUP(A14,Sheet2!A:B,2,0) -> Americas | F14: Deposited | G14: PMT-S151-167535 | I14: USD | J14: -18060 | K14: -18060 | L14: 18060 | M14: -18060 | N14: Sun Valley Resort | P14: CHECK
A15: 102 - US | B15: 44652 | C15: =UPPER(TEXT(B15, "[$-en-US]mmmm")) -> APRIL | D15: =YEAR(B15) -> 2022 | E15: =VLOOKUP(A15,Sheet2!A:B,2,0) -> Americas | F15: Deposited | G15: PMT-S151-145279 | I15: USD | J15: -17850.4 | K15: -17850.4 | L15: 17850.4 | M15: -17850.4 | N15: Netchoice | P15: FOREIGN REMITTANCE CREDIT 33RECD CHIP WELLS FARGO BANK,SAN FRANCISCO,CA*O RG:NETCHOICE,US 20005-3417,WASHINGTON DC,1401 K S*BNF:MELTWATER NEW S US INC,SAN FRANCISCO CA/US,STE 100*OBI:INVOICE S151 535230*STCHIPSEQ :0499781*TIME:1511*YOUR REF:643*OUR REF:091587415
A16: 102 - US | B16: 46132 | C16: =UPPER(TEXT(B16, "[$-en-US]mmmm")) -> APRIL | D16: =YEAR(B16) -> 2026 | E16: =VLOOKUP(A16,Sheet2!A:B,2,0) -> Americas | F16: Deposited | G16: PMT-S151-223019 | I16: USD | J16: -17200 | K16: -17200 | L16: 17200 | M16: 0 | N16: Gordon State College | P16: ACH CONCENTRATION CREDIT ACH CORP TRADE PAYMENT FROM Gordon State Col Gordon St CTX 0000039074
A17: 102 - US | B17: 44907 | C17: =UPPER(TEXT(B17, "[$-en-US]mmmm")) -> DECEMBER | D17: =YEAR(B17) -> 2022 | E17: =VLOOKUP(A17,Sheet2!A:B,2,0) -> Americas | F17: Deposited | G17: PMT-S151-159463 | I17: USD | J17: -16500 | K17: -16500 | L17: 16500 | M17: 3500 | N17: Bayhealth Medical Center | P17: CHECK
A18: 102 - US | B18: 46143 | C18: =UPPER(TEXT(B18, "[$-en-US]mmmm")) -> MAY | D18: =YEAR(B18) -> 2026 | E18: =VLOOKUP(A18,Sheet2!A:B,2,0) -> Americas | F18: Deposited | G18: PMT-S151-223708 | I18: USD | J18: -16483 | K18: -16483 | L18: 16483 | M18: -16483 | N18: Washington Times Global Media Group | O18: Jordan Irvine | P18: ACH CREDIT ACH DEPOSIT FROM WASHINGTON TIMES-CREDITS WASHINGTO CREDITS TWT-22920
A19: 102 - US | B19: 46056 | C19: =UPPER(TEXT(B19, "[$-en-US]mmmm")) -> FEBRUARY | D19: =YEAR(B19) -> 2026 | E19: =VLOOKUP(A19,Sheet2!A:B,2,0) -> Americas | F19: Deposited | G19: PMT-S151-218617 | H19: IN-S151-589402 | I19: USD | J19: -16000 | K19: -16000 | L19: 15999.84 | M19: -15999.84 | N19: West Palm Beach Downtown Development Authority | O19: Jose Castellanos
A20: 102 - US | B20: 44680 | C20: =UPPER(TEXT(B20, "[$-en-US]mmmm")) -> APRIL | D20: =YEAR(B20) -> 2022 | E20: =VLOOKUP(A20,Sheet2!A:B,2,0) -> Americas | F20: Deposited | G20: PMT-S151-146709 | I20: USD | J20: -15750 | K20: -15750 | L20: 15750 | M20: -15750 | N20: Kean University | O20: Kristin Walsh
A21: 102 - US | B21: 46139 | C21: =UPPER(TEXT(B21, "[$-en-US]mmmm")) -> APRIL | D21: =YEAR(B21) -> 2026 | E21: =VLOOKUP(A21,Sheet2!A:B,2,0) -> Americas | F21: Deposited | G21: PMT-S151-223397 | I21: USD | J21: -15000 | K21: -15000 | L21: 15000 | M21: -15000 | N21: Nautilus Solar Energy, LLC | P21: ACH CONCENTRATION CREDIT ACH CASH CONCENTRATION NAUTILUS SOLAR E-ACH PMT NAUTILUS ACH Pmt 11216430243
A22: 102 - US | B22: 45996 | C22: =UPPER(TEXT(B22, "[$-en-US]mmmm")) -> DECEMBER | D22: =YEAR(B22) -> 2025 | E22: =VLOOKUP(A22,Sheet2!A:B,2,0) -> Americas | F22: Deposited | G22: PMT-S151-215069 | I22: USD | J22: -14145.99 | K22: -14145.99 | L22: 14145.99 | M22: 154725.09 | N22: Amazon.com Services LLC | P22: ACH CONCENTRATION CREDIT ACH CASH CONCENTRATION AMAZON.COM-EDI PYMNTS AMAZON.CO EDI PYMNTS DAS4VG6U2FWEEBQ
A23: 102 - US | B23: 45614 | C23: =UPPER(TEXT(B23, "[$-en-US]mmmm")) -> NOVEMBER | D23: =YEAR(B23) -> 2024 | E23: =VLOOKUP(A23,Sheet2!A:B,2,0) -> Americas | F23: Deposited | G23: PMT-S151-196679 | I23: USD | J23: -13975 | K23: -13975 | L23: 13975 | M23: -250567.82 | N23: DUMMY CUSTOMER_CASHAPPS 102 - US | P23: FOREIGN REMITTANCE CREDIT 33RECD CHIP JPMORGAN CHASE BANK*ORG:BYTECHIP LLC,UNITED STATES,US ,8 THE GREEN, SUITE B, DOVE*OGB:RD WALLET TECHNOLOGIES LIMITED,CAUSEWAY BAY,535 JAFFE RO*BNF:MELTWATER NEWS US INC,REDWOOD CITY CA/US,STE 165*OBI:202411080803*STCHIPSEQ:00209649*TIME:0248 *YOUR REF:1513OT8581513*OUR REF:323200531
A24: 102 - US | B24: 44694 | C24: =UPPER(TEXT(B24, "[$-en-US]mmmm")) -> MAY | D24: =YEAR(B24) -> 2022 | E24: =VLOOKUP(A24,Sheet2!A:B,2,0) -> Americas | F24: Deposited | G24: PMT-S151-147498 | I24: USD | J24: -13650 | K24: -13650 | L24: 13650 | M24: -13650 | N24: Florida Dept. of Agriculture and Consumer Services | O24: Jordan Irvine | P24: CHECK
A25: 102 - US | B25: 45910 | C25: =UPPER(TEXT(B25, "[$-en-US]mmmm")) -> SEPTEMBER | D25: =YEAR(B25) -> 2025 | E25: =VLOOKUP(A25,Sheet2!A:B,2,0) -> Americas | F25: Deposited | G25: PMT-S151-210583 | I25: USD | J25: -13564.62 | K25: -13564.62 | L25: 13564.62 | M25: -13564.62 | N25: Cubic Corporation | O25: Jose Castellanos | P25: Customer refund ACH CONCENTRATION CREDIT ACH CASH CONCENTRATION CUBIC CORPORATIO-EDI/ACH Cubic Cor EDI/ACH 10152000245 624
A26: 102 - US | B26: 45167 | C26: =UPPER(TEXT(B26, "[$-en-US]mmmm")) -> AUGUST | D26: =YEAR(B26) -> 2023 | E26: =VLOOKUP(A26,Sheet2!A:B,2,0) -> Americas | F26: Deposited | G26: PMT-S151-173898 | I26: USD | J26: -13500 | K26: -13500 | L26: 13500 | M26: -13500 | N26: Versant Health | P26: CHECK
A27: 102 - US | B27: 45085 | C27: =UPPER(TEXT(B27, "[$-en-US]mmmm")) -> JUNE | D27: =YEAR(B27) -> 2023 | E27: =VLOOKUP(A27,Sheet2!A:B,2,0) -> Americas | F27: Deposited | G27: PMT-S151-169476 | I27: USD | J27: -12980 | K27: -12980 | L27: 12980 | M27: -250567.82 | N27: DUMMY CUSTOMER_CASHAPPS 102 - US | P27: ACH CONCENTRATION CREDIT ACH CASH CONCENTRATION DALLAS FOUNDATIO-CORP PAY DALLAS FO CORP PAY 1504
A28: 102 - US | B28: 44830 | C28: =UPPER(TEXT(B28, "[$-en-US]mmmm")) -> SEPTEMBER | D28: =YEAR(B28) -> 2022 | E28: =VLOOKUP(A28,Sheet2!A:B,2,0) -> Americas | F28: Deposited | G28: PMT-S151-154814 | I28: USD | J28: -11550 | K28: -11550 | L28: 11550 | M28: -11550 | N28: AmeriCU Credit Union | P28: CHECK
A29: 102 - US | B29: 45174 | C29: =UPPER(TEXT(B29, "[$-en-US]mmmm")) -> SEPTEMBER | D29: =YEAR(B29) -> 2023 | E29: =VLOOKUP(A29,Sheet2!A:B,2,0) -> Americas | F29: Deposited | G29: PMT-S151-174242 | H29: IN-S151-555435 | I29: USD | J29: -22698.13 | K29: -22698.13 | L29: 11349.07 | M29: -11349.07 | N29: Drive Agency, LLC | O29: Yangzom Vitali-116 | P29: ACH CREDIT ACH DEPOSIT FROM GREENBERG QUINLA-ACH PAYMNT INV IN-S151-548883
A30: 102 - US | B30: 46136 | C30: =UPPER(TEXT(B30, "[$-en-US]mmmm")) -> APRIL | D30: =YEAR(B30) -> 2026 | E30: =VLOOKUP(A30,Sheet2!A:B,2,0) -> Americas | F30: Deposited | G30: PMT-S151-223327 | I30: USD | J30: -9900 | K30: -9900 | L30: 9900 | M30: -250567.82 | N30: DUMMY CUSTOMER_CASHAPPS 102 - US | P30: ACH CONCENTRATION CREDIT ACH CASH CONCENTRATION COMMISSION L'UNI-PAYMENT COMMISSIO PAYMENT KQ3LUSEQGD69
A31: 102 - US | B31: 45114 | C31: =UPPER(TEXT(B31, "[$-en-US]mmmm")) -> JULY | D31: =YEAR(B31) -> 2023 | E31: =VLOOKUP(A31,Sheet2!A:B,2,0) -> Americas | F31: Deposited | G31: PMT-S151-171074 | I31: USD | J31: -9695 | K31: -9695 | L31: 9695 | M31: -10420 | N31: Amarin Pharma, Inc. | O31: Sarah Shoemaker-MW | P31: FOREIGN REMITTANCE CREDIT 33RECD CHIP JPMORGAN CHASE BANK*ORG:AMARIN SWITZERLAND GMBH,CH/ZUG 6300,BAARERSTRASSE 75*OGB:JPMORGAN CHASE BANK,N.A.,ZUERICH,DREI KOENIGSTRASSE 21*BNF:MELTWATER NEWS US INC,REDWOOD CITY CA/US,STE 165 *OBI:/ROC/714*STCHIPSEQ:0157130*TIME:0207*YOUR REF:SWF OF 23/07/07*OUR REF:18 8409072
A32: 102 - US | B32: 45684 | C32: =UPPER(TEXT(B32, "[$-en-US]mmmm")) -> JANUARY | D32: =YEAR(B32) -> 2025 | E32: =VLOOKUP(A32,Sheet2!A:B,2,0) -> Americas | F32: Deposited | G32: PMT-S151-199815 | I32: USD | J32: -9680 | K32: -9680 | L32: 9680 | M32: -9680 | N32: Zonda Home | P32: ACH CONCENTRATION CREDIT ACH CASH CONCENTRATION METROSTUDY INC-AB-TFBANIP METROSTUD AB-TFBANIP 4090116
A33: 102 - US | B33: 46031 | C33: =UPPER(TEXT(B33, "[$-en-US]mmmm")) -> JANUARY | D33: =YEAR(B33) -> 2026 | E33: =VLOOKUP(A33,Sheet2!A:B,2,0) -> Americas | F33: Deposited | G33: PMT-S151-217064 | I33: USD | J33: -9600 | K33: -9600 | L33: 9600 | M33: -9600 | N33: Hunstville Botanical Garden | P33: ACH CONCENTRATION CREDIT ACH CASH CONCENTRATION HSV BG 517-ACH PAYMEN HSV BG ACH Paymen 32465974
A34: 102 - US | B34: 44852 | C34: =UPPER(TEXT(B34, "[$-en-US]mmmm")) -> OCTOBER | D34: =YEAR(B34) -> 2022 | E34: =VLOOKUP(A34,Sheet2!A:B,2,0) -> Americas | F34: Deposited | G34: PMT-S151-156313 | H34: IN-S151-546649 | I34: USD | J34: -14000 | K34: -14000 | L34: 9333.33 | M34: -9333.33 | N34: Management & Training Corporation (Job Corps) | O34: Jose Castellanos-103 | P34: renewal 12/7/22-12/6/25
A35: 102 - US | B35: 44736 | C35: =UPPER(TEXT(B35, "[$-en-US]mmmm")) -> JUNE | D35: =YEAR(B35) -> 2022 | E35: =VLOOKUP(A35,Sheet2!A:B,2,0) -> Americas | F35: Deposited | G35: PMT-S151-149470 | I35: USD | J35: -8250 | K35: -8250 | L35: 8250 | M35: -8250 | N35: Avendra | P35: CHECK
A36: 102 - US | B36: 44748 | C36: =UPPER(TEXT(B36, "[$-en-US]mmmm")) -> JULY | D36: =YEAR(B36) -> 2022 | E36: =VLOOKUP(A36,Sheet2!A:B,2,0) -> Americas | F36: Deposited | G36: PMT-S151-150211 | I36: USD | J36: -8250 | K36: -8250 | L36: 8250 | M36: -250567.82 | N36: DUMMY CUSTOMER_CASHAPPS 102 - US | P36: ACH CONCENTRATION CREDIT ACH CASH CONCENTRATION INDIANA UNV-BATCH INDIANA U BATCH 504301824
A37: 102 - US | B37: 44956 | C37: =UPPER(TEXT(B37, "[$-en-US]mmmm")) -> JANUARY | D37: =YEAR(B37) -> 2023 | E37: =VLOOKUP(A37,Sheet2!A:B,2,0) -> Americas | F37: Deposited | G37: PMT-S151-162604 | H37: IN-S151-549189 | I37: USD | J37: -15665.62 | K37: -15665.62 | L37: 8165.62 | M37: -8165.62 | N37: Comic Relief, Inc | P37: ACH CONCENTRATION CREDIT ACH CASH CONCENTRATION COMIC RELIEF8654-PAYMENTS COMIC REL PAYMENTS Meltwater N ews
A38: 102 - US | B38: 45856 | C38: =UPPER(TEXT(B38, "[$-en-US]mmmm")) -> JULY | D38: =YEAR(B38) -> 2025 | E38: =VLOOKUP(A38,Sheet2!A:B,2,0) -> Americas | F38: Deposited | G38: PMT-S151-208027 | I38: USD | J38: -7720.17 | K38: -7720.17 | L38: 7720.17 | M38: -250567.82 | N38: DUMMY CUSTOMER_CASHAPPS 102 - US | P38: ACH CONCENTRATION CREDIT ACH CASH CONCENTRATION ENVIOLOL-PAYMENTS ENVIOLOL PAYMENTS 0000010634
A39: 102 - US | B39: 45881 | C39: =UPPER(TEXT(B39, "[$-en-US]mmmm")) -> AUGUST | D39: =YEAR(B39) -> 2025 | E39: =VLOOKUP(A39,Sheet2!A:B,2,0) -> Americas | F39: Deposited | G39: PMT-S151-209317 | I39: USD | J39: -7652 | K39: -7652 | L39: 7652 | M39: -7652 | N39: Fort Worth Symphony Orchestra
A40: 102 - US | B40: 46126 | C40: =UPPER(TEXT(B40, "[$-en-US]mmmm")) -> APRIL | D40: =YEAR(B40) -> 2026 | E40: =VLOOKUP(A40,Sheet2!A:B,2,0) -> Americas | F40: Deposited | G40: PMT-S151-222677 | I40: USD | J40: -7500 | K40: -7500 | L40: 7500 | M40: -250567.82 | N40: DUMMY CUSTOMER_CASHAPPS 102 - US
...

Sheet Copy Netsuite Report
A1: Subsidiary (no hierarchy) | B1: Date | C1: Status | D1: Number | E1: Invoice Number | F1: Currency | G1: Amount Base | H1: Amount USD | I1: Amount Remaining | J1: Balance | K1: Customer Name | L1: AR Specialist | M1: Memo
A2: 102 - US | B2: 45736 | C2: Deposited | D2: PMT-S151-202999 | F2: USD | G2: -81229.11 | H2: -81229.11 | I2: 81229.11 | J2: -250567.82 | K2: DUMMY CUSTOMER_CASHAPPS 102 - US | M2: ACH CONCENTRATION CREDIT ACH CORP TRADE PAYMENT FROM MICROSOFT MICROSOFT 0004992933 68251185441010
A3: 102 - US | B3: 45922 | C3: Deposited | D3: PMT-S151-211138 | F3: USD | G3: -54445.55 | H3: -54445.55 | I3: 54445.55 | J3: -50095.55 | K3: Microsoft Corporation | M3: ACH CONCENTRATION CREDIT ACH CORP TRADE PAYMENT FROM MICROSOFT MICROSOFT 0005317824 68550845931010
A4: 102 - US | B4: 46071 | C4: Deposited | D4: PMT-S151-219775 | F4: USD | G4: -35534 | H4: -35534 | I4: 35534 | J4: -35534 | K4: Brick Media | M4: INCOMING MONEY TRANSFER 53RECD FED JPMORGAN CHASE BANK*ORG:BRICK MEDIA LLC,RO CKY RIVER OH 44116-1815 US,19885 DETRO*OGB:JPMORGAN CHASE BANK,TAMPA,10410 HI GHLAND MANOR DRIVE*BNF:MELTWATER NEWS US INC,REDWOOD CITY CA/US,275 S HO*STFEDSEQ:B1Q8982R000363*TIME:0341*YOUR REF:WTH OF 26/02/18*OUR REF:0490937 10
A5: 102 - US | B5: 45691 | C5: Deposited | D5: PMT-S151-200395 | F5: USD | G5: -32613.85 | H5: -32613.85 | I5: 32613.85 | J5: -250567.82 | K5: DUMMY CUSTOMER_CASHAPPS 102 - US | M5: ACH CONCENTRATION CREDIT ACH CORP TRADE PAYMENT FROM MICROSOFT MICROSOFT 0004890122 68550745441010
A6: 102 - US | B6: 44851 | C6: Deposited | D6: PMT-S151-156272 | F6: USD | G6: -27218.77 | H6: -27218.77 | I6: 27218.77 | J6: -27218.77 | K6: ComplySci | M6: ACH CONCENTRATION CREDIT ACH CASH CONCENTRATION COMPLYSCI-PAYMENT ComplySci Payment 46810
A7: 102 - US | B7: 45856 | C7: Deposited | D7: PMT-S151-208003 | F7: USD | G7: -25699.72 | H7: -25699.72 | I7: 25699.72 | J7: -250567.82 | K7: DUMMY CUSTOMER_CASHAPPS 102 - US | M7: ACH CONCENTRATION CREDIT ACH CASH CONCENTRATION ENVIOLOL-PAYMENTS ENVIOLOL PAYMENTS 0000010593
A8: 102 - US | B8: 45838 | C8: Deposited | D8: PMT-S151-207105 | F8: USD | G8: -24128 | H8: -24128 | I8: 24128 | J8: -250567.82 | K8: DUMMY CUSTOMER_CASHAPPS 102 - US | M8: ACH CONCENTRATION CREDIT ACH CORP TRADE PAYMENT FROM MICROSOFT MICROSOFT 0005162418 68500854311010
A9: 102 - US | B9: 46118 | C9: Deposited | D9: PMT-S151-222326 | F9: USD | G9: -20913.77 | H9: -20913.77 | I9: 20913.77 | J9: -20913.77 | K9: Camp Chef | M9: ACH CONCENTRATION CREDIT ACH CASH CONCENTRATION BUSHNELL OPER-PAYMENT BUSHNELL PAYMENT 2021416
A10: 102 - US | B10: 46127 | C10: Deposited | D10: PMT-S151-222780 | F10: USD | G10: -20698 | H10: -20698 | I10: 20698 | J10: -20698 | K10: Culloton + Bauer Luce | M10: ACH CONCENTRATION CREDIT ACH CASH CONCENTRATION CULLOTON STRATEG-ACH PAYMEN Culloton ACH Paymen 95267
A11: 102 - US | B11: 45889 | C11: Deposited | D11: PMT-S151-209700 | F11: USD | G11: -20000 | H11: -20000 | I11: 20000 | J11: -50095.55 | K11: Microsoft Corporation | M11: ACH CONCENTRATION CREDIT ACH CORP TRADE PAYMENT FROM MICROSOFT MICROSOFT 0005263117 68151120631010
A12: 102 - US | B12: 46108 | C12: Deposited | D12: PMT-S151-221843 | E12: PMT-S151-221843 | F12: USD | G12: -39600 | H12: -39600 | I12: 19800 | J12: -19800 | K12: Blue Learning | M12: ACH CONCENTRATION CREDIT ACH CASH CONCENTRATION BLUE LEARNING OP-CORP PAY BLUE LEAR CORP PAY 10957
A13: 102 - US | B13: 46108 | C13: Deposited | D13: PMT-S151-221843 | E13: IN-S151-593360 | F13: USD | G13: -39600 | H13: -39600 | I13: 19800 | J13: -19800 | K13: Blue Learning | M13: ACH CONCENTRATION CREDIT ACH CASH CONCENTRATION BLUE LEARNING OP-CORP PAY BLUE LEAR CORP PAY 10957
A14: 102 - US | B14: 46139 | C14: Deposited | D14: PMT-S151-223322 | F14: USD | G14: -19350 | H14: -19350 | I14: 19350 | J14: -19350 | K14: Gaudenzia, Inc
A15: 102 - US | B15: 45049 | C15: Deposited | D15: PMT-S151-167535 | F15: USD | G15: -18060 | H15: -18060 | I15: 18060 | J15: -18060 | K15: Sun Valley Resort | M15: CHECK
A16: 102 - US | B16: 44652 | C16: Deposited | D16: PMT-S151-145279 | F16: USD | G16: -17850.4 | H16: -17850.4 | I16: 17850.4 | J16: -17850.4 | K16: Netchoice | M16: FOREIGN REMITTANCE CREDIT 33RECD CHIP WELLS FARGO BANK,SAN FRANCISCO,CA*O RG:NETCHOICE,US 20005-3417,WASHINGTON DC,1401 K S*BNF:MELTWATER NEW S US INC,SAN FRANCISCO CA/US,STE 100*OBI:INVOICE S151 535230*STCHIPSEQ :0499781*TIME:1511*YOUR REF:643*OUR REF:091587415
A17: 102 - US | B17: 46132 | C17: Deposited | D17: PMT-S151-223019 | F17: USD | G17: -17200 | H17: -17200 | I17: 17200 | J17: 0 | K17: Gordon State College | M17: ACH CONCENTRATION CREDIT ACH CORP TRADE PAYMENT FROM Gordon State Col Gordon St CTX 0000039074
A18: 102 - US | B18: 44907 | C18: Deposited | D18: PMT-S151-159463 | F18: USD | G18: -16500 | H18: -16500 | I18: 16500 | J18: 3500 | K18: Bayhealth Medical Center | M18: CHECK
A19: 102 - US | B19: 46143 | C19: Deposited | D19: PMT-S151-223708 | F19: USD | G19: -16483 | H19: -16483 | I19: 16483 | J19: -16483 | K19: Washington Times Global Media Group | L19: Jordan Irvine | M19: ACH CREDIT ACH DEPOSIT FROM WASHINGTON TIMES-CREDITS WASHINGTO CREDITS TWT-22920
A20: 102 - US | B20: 46056 | C20: Deposited | D20: PMT-S151-218617 | E20: IN-S151-589402 | F20: USD | G20: -16000 | H20: -16000 | I20: 15999.84 | J20: -15999.84 | K20: West Palm Beach Downtown Development Authority | L20: Jose Castellanos
A21: 102 - US | B21: 44680 | C21: Deposited | D21: PMT-S151-146709 | F21: USD | G21: -15750 | H21: -15750 | I21: 15750 | J21: -15750 | K21: Kean University | L21: Kristin Walsh
A22: 102 - US | B22: 46139 | C22: Deposited | D22: PMT-S151-223397 | F22: USD | G22: -15000 | H22: -15000 | I22: 15000 | J22: -15000 | K22: Nautilus Solar Energy, LLC | M22: ACH CONCENTRATION CREDIT ACH CASH CONCENTRATION NAUTILUS SOLAR E-ACH PMT NAUTILUS ACH Pmt 11216430243
A23: 102 - US | B23: 45996 | C23: Deposited | D23: PMT-S151-215069 | F23: USD | G23: -14145.99 | H23: -14145.99 | I23: 14145.99 | J23: 154725.09 | K23: Amazon.com Services LLC | M23: ACH CONCENTRATION CREDIT ACH CASH CONCENTRATION AMAZON.COM-EDI PYMNTS AMAZON.CO EDI PYMNTS DAS4VG6U2FWEEBQ
A24: 102 - US | B24: 45614 | C24: Deposited | D24: PMT-S151-196679 | F24: USD | G24: -13975 | H24: -13975 | I24: 13975 | J24: -250567.82 | K24: DUMMY CUSTOMER_CASHAPPS 102 - US | M24: FOREIGN REMITTANCE CREDIT 33RECD CHIP JPMORGAN CHASE BANK*ORG:BYTECHIP LLC,UNITED STATES,US ,8 THE GREEN, SUITE B, DOVE*OGB:RD WALLET TECHNOLOGIES LIMITED,CAUSEWAY BAY,535 JAFFE RO*BNF:MELTWATER NEWS US INC,REDWOOD CITY CA/US,STE 165*OBI:202411080803*STCHIPSEQ:00209649*TIME:0248 *YOUR REF:1513OT8581513*OUR REF:323200531
A25: 102 - US | B25: 44694 | C25: Deposited | D25: PMT-S151-147498 | F25: USD | G25: -13650 | H25: -13650 | I25: 13650 | J25: -13650 | K25: Florida Dept. of Agriculture and Consumer Services | L25: Jordan Irvine | M25: CHECK
A26: 102 - US | B26: 45910 | C26: Deposited | D26: PMT-S151-210583 | F26: USD | G26: -13564.62 | H26: -13564.62 | I26: 13564.62 | J26: -13564.62 | K26: Cubic Corporation | L26: Jose Castellanos | M26: Customer refund ACH CONCENTRATION CREDIT ACH CASH CONCENTRATION CUBIC CORPORATIO-EDI/ACH Cubic Cor EDI/ACH 10152000245 624
A27: 102 - US | B27: 45167 | C27: Deposited | D27: PMT-S151-173898 | F27: USD | G27: -13500 | H27: -13500 | I27: 13500 | J27: -13500 | K27: Versant Health | M27: CHECK
A28: 102 - US | B28: 45085 | C28: Deposited | D28: PMT-S151-169476 | F28: USD | G28: -12980 | H28: -12980 | I28: 12980 | J28: -250567.82 | K28: DUMMY CUSTOMER_CASHAPPS 102 - US | M28: ACH CONCENTRATION CREDIT ACH CASH CONCENTRATION DALLAS FOUNDATIO-CORP PAY DALLAS FO CORP PAY 1504
A29: 102 - US | B29: 44830 | C29: Deposited | D29: PMT-S151-154814 | F29: USD | G29: -11550 | H29: -11550 | I29: 11550 | J29: -11550 | K29: AmeriCU Credit Union | M29: CHECK
A30: 102 - US | B30: 45174 | C30: Deposited | D30: PMT-S151-174242 | E30: IN-S151-555435 | F30: USD | G30: -22698.13 | H30: -22698.13 | I30: 11349.07 | J30: -11349.07 | K30: Drive Agency, LLC | L30: Yangzom Vitali-116 | M30: ACH CREDIT ACH DEPOSIT FROM GREENBERG QUINLA-ACH PAYMNT INV IN-S151-548883
A31: 102 - US | B31: 46136 | C31: Deposited | D31: PMT-S151-223327 | F31: USD | G31: -9900 | H31: -9900 | I31: 9900 | J31: -250567.82 | K31: DUMMY CUSTOMER_CASHAPPS 102 - US | M31: ACH CONCENTRATION CREDIT ACH CASH CONCENTRATION COMMISSION L'UNI-PAYMENT COMMISSIO PAYMENT KQ3LUSEQGD69
A32: 102 - US | B32: 45114 | C32: Deposited | D32: PMT-S151-171074 | F32: USD | G32: -9695 | H32: -9695 | I32: 9695 | J32: -10420 | K32: Amarin Pharma, Inc. | L32: Sarah Shoemaker-MW | M32: FOREIGN REMITTANCE CREDIT 33RECD CHIP JPMORGAN CHASE BANK*ORG:AMARIN SWITZERLAND GMBH,CH/ZUG 6300,BAARERSTRASSE 75*OGB:JPMORGAN CHASE BANK,N.A.,ZUERICH,DREI KOENIGSTRASSE 21*BNF:MELTWATER NEWS US INC,REDWOOD CITY CA/US,STE 165 *OBI:/ROC/714*STCHIPSEQ:0157130*TIME:0207*YOUR REF:SWF OF 23/07/07*OUR REF:18 8409072
A33: 102 - US | B33: 45684 | C33: Deposited | D33: PMT-S151-199815 | F33: USD | G33: -9680 | H33: -9680 | I33: 9680 | J33: -9680 | K33: Zonda Home | M33: ACH CONCENTRATION CREDIT ACH CASH CONCENTRATION METROSTUDY INC-AB-TFBANIP METROSTUD AB-TFBANIP 4090116
A34: 102 - US | B34: 46031 | C34: Deposited | D34: PMT-S151-217064 | F34: USD | G34: -9600 | H34: -9600 | I34: 9600 | J34: -9600 | K34: Hunstville Botanical Garden | M34: ACH CONCENTRATION CREDIT ACH CASH CONCENTRATION HSV BG 517-ACH PAYMEN HSV BG ACH Paymen 32465974
A35: 102 - US | B35: 44852 | C35: Deposited | D35: PMT-S151-156313 | E35: IN-S151-546649 | F35: USD | G35: -14000 | H35: -14000 | I35: 9333.33 | J35: -9333.33 | K35: Management & Training Corporation (Job Corps) | L35: Jose Castellanos-103 | M35: renewal 12/7/22-12/6/25
A36: 102 - US | B36: 44736 | C36: Deposited | D36: PMT-S151-149470 | F36: USD | G36: -8250 | H36: -8250 | I36: 8250 | J36: -8250 | K36: Avendra | M36: CHECK
A37: 102 - US | B37: 44748 | C37: Deposited | D37: PMT-S151-150211 | F37: USD | G37: -8250 | H37: -8250 | I37: 8250 | J37: -250567.82 | K37: DUMMY CUSTOMER_CASHAPPS 102 - US | M37: ACH CONCENTRATION CREDIT ACH CASH CONCENTRATION INDIANA UNV-BATCH INDIANA U BATCH 504301824
A38: 102 - US | B38: 44956 | C38: Deposited | D38: PMT-S151-162604 | E38: IN-S151-549189 | F38: USD | G38: -15665.62 | H38: -15665.62 | I38: 8165.62 | J38: -8165.62 | K38: Comic Relief, Inc | M38: ACH CONCENTRATION CREDIT ACH CASH CONCENTRATION COMIC RELIEF8654-PAYMENTS COMIC REL PAYMENTS Meltwater N ews
A39: 102 - US | B39: 45856 | C39: Deposited | D39: PMT-S151-208027 | F39: USD | G39: -7720.17 | H39: -7720.17 | I39: 7720.17 | J39: -250567.82 | K39: DUMMY CUSTOMER_CASHAPPS 102 - US | M39: ACH CONCENTRATION CREDIT ACH CASH CONCENTRATION ENVIOLOL-PAYMENTS ENVIOLOL PAYMENTS 0000010634
A40: 102 - US | B40: 45881 | C40: Deposited | D40: PMT-S151-209317 | F40: USD | G40: -7652 | H40: -7652 | I40: 7652 | J40: -7652 | K40: Fort Worth Symphony Orchestra
...

Sheet Sheet2
A1: 102 - US | B1: Americas
A2: 105 - Owler | B2: Americas
A3: 107 - Linkfluence Corp | B3: Americas
A4: 10C (106) - Sysomos US | B4: Sysomos
A5: 111 - Canada | B5: Americas
A6: 11C (116) - Meltwater News Canada 2 | B6: Sysomos
A7: 131 - Brazil | B7: Americas
A8: 201 - Australia | B8: APAC
A9: 211 - China | B9: APAC
A10: 221 - HK | B10: APAC
A11: 231 - Japan | B11: APAC
A12: 241 - Singapore | B12: APAC
... A33: 335 - Scoop.it SAS | B33: EMEA

Sheet AMERICAS APRIL 2026
A1: Date | B1: Amount Remaining | C1: Number | D1: Customer Name | E1: AR Specialist | F1: Memo
A2: 46118 | B2: 20913.77 | C2: PMT-S151-222326 | D2: Camp Chef | F2: ACH CONCENTRATION CREDIT ACH CASH CONCENTRATION BUSHNELL OPER-PAYMENT BUSHNELL PAYMENT 2021416
A3: 46127 | B3: 20698 | C3: PMT-S151-222780 | D3: Culloton + Bauer Luce | F3: ACH CONCENTRATION CREDIT ACH CASH CONCENTRATION CULLOTON STRATEG-ACH PAYMEN Culloton ACH Paymen 95267
A4: 46139 | B4: 19350 | C4: PMT-S151-223322 | D4: Gaudenzia, Inc
A5: 46132 | B5: 17200 | C5: PMT-S151-223019 | D5: Gordon State College | F5: ACH CONCENTRATION CREDIT ACH CORP TRADE PAYMENT FROM Gordon State Col Gordon St CTX 0000039074
A6: 46139 | B6: 15000 | C6: PMT-S151-223397 | D6: Nautilus Solar Energy, LLC | F6: ACH CONCENTRATION CREDIT ACH CASH CONCENTRATION NAUTILUS SOLAR E-ACH PMT NAUTILUS ACH Pmt 11216430243
A7: 46136 | B7: 9900 | C7: PMT-S151-223327 | D7: DUMMY CUSTOMER_CASHAPPS 102 - US | F7: ACH CONCENTRATION CREDIT ACH CASH CONCENTRATION COMMISSION L'UNI-PAYMENT COMMISSIO PAYMENT KQ3LUSEQGD69
A8: 46126 | B8: 7500 | C8: PMT-S151-222677 | D8: DUMMY CUSTOMER_CASHAPPS 102 - US
A9: 46136 | B9: 6200 | C9: PMT-S151-223212 | D9: Honolulu Marathon Association | E9: Stephanie Thore
A10: 46135 | B10: 4265.16 | C10: PMT-S151-223214 | D10: TFI Family Services, Inc. | F10: ACH CONCENTRATION CREDIT ACH CASH CONCENTRATION TFI FAMILY SERVI-ACH PAYMEN TFI Famil ACH Paymen V000000551
A11: 46113 | B11: 10 | C11: PMT-S151-222271 | D11: The Stronach Group | F11: ACH CONCENTRATION CREDIT ACH CASH CONCENTRATION 1/ST LLC-PAYMENTJNL 1/ST LLC PAYMENTJNL MELTW-CORP
A12: 46140 | B12: 49625.782 | C12: PMT-S130-48216 | D12: DUMMY CUSTOMER_CASHAPPS 111 - Canada | F12: ACH: THE CURRENCY CL THE CURRENCY CLOUD LIMITED RE:Meltwater News Canada Inc
A13: 46120 | B13: 2104.691 | C13: PMT-S130-48077 | D13: Weber Shandwick | E13: Frida Emri | F13: ACH: Weber Shandwick WEBER SHANDWICK CAN RE:MELTWATER NEWS CANADA INC
A14: 46113 | B14: 220.631 | C14: PMT-S130-48041 | D14: Wellington Altus Private Wealth | F14: ACH: WELLINGTONALTUS WELLINGTONALTUSPRIVATEWEALTH RE:MELTWATER NEWS CANADA INC

Sheet APAC APRIL 2026
A1: Date | B1: Amount Remaining | C1: Number | D1: Customer Name | E1: AR Specialist | F1: Memo
A2: 46121 | B2: 13203.96 | C2: PMT-S155-42950 | D2: DUMMY CUSTOMER_CASHAPPS 201 - Australia | E2: Windy Go | F2: 173200023166926 MARS NEDERLAND B 0001975
A3: 46133 | B3: 11789.25 | C3: PMT-S155-43051 | D3: DUMMY CUSTOMER_CASHAPPS 201 - Australia | E3: Windy Go | F3: Meltwater Pont3 Pty Limite 0599873
A4: 46136 | B4: 529.445 | C4: PMT-S155-43101 | D4: DUMMY CUSTOMER_CASHAPPS 201 - Australia | E4: Windy Go | F4: 689647123400424153 VERVESUPER 0780254
A5: 46132 | B5: 201.025 | C5: PMT-S155-43042 | D5: DUMMY CUSTOMER_CASHAPPS 201 - Australia | E5: Windy Go | F5: CVENTPAYMENTS-DMRH CVENTPAYMENTS 0530766
A6: 46139 | B6: 134.84 | C6: PMT-S155-43111 | D6: DUMMY CUSTOMER_CASHAPPS 201 - Australia | E6: Windy Go | F6: CVENTPAYMENTS-HRNO CVENTPAYMENTS 0832990
A7: 46127 | B7: 3822.059 | C7: PMT-S158-12595 | D7: Suyen Corporation | F7: Payment for 241-Singapore IN-S158-410328 received in 221-HK
A8: 46127 | B8: 3351.286 | C8: PMT-S158-12593 | D8: SM PRIME HOLDINGS INC. | F8: 1/SM PRIME HOLDINGS INC IN S158 410331 SOCIAL MEDIA CRISIS MANAGEMENT SUBSCRIPTION FX USD 32076.80 AT 1.2459590 528325969 /TMS/2026-04-15T08:14:19 GMT/MID/1.271462
A9: 46142 | B9: 1498.977 | C9: PMT-S158-12708 | D9: St. Luke's Medical Center | F9: ST LUKE S MEDICAL CENTER GLOBAL CIT IN S158 410605 CA ADDITIONAL SEARCH ES USERS AND SITE REVIEWS FX USD 14235.50 AT 1.2544360 529153071 /TMS/2026-04-30T01:17:09 GMT/MID/1.280822
A10: 46128 | B10: 777.741 | C10: PMT-S158-12609 | D10: Intelligent Beauty Skin Solutions, Inc. Business Style: Belo Medical Group | F10: INTELLIGENT BEAUTY SKIN SOLUTIONS I IN S158 410316 HO FX USD 7433.00 AT 1.2453140 528384503/TMS/2026-04-16T07:40:19 GMT/MID/1.270803
A11: 46140 | B11: 535.863 | C11: PMT-S158-12678 | D11: LouderPH | F11: 1/LOUDERPH INC /URI/OTHER-PAYMENT OF MONTHLY SUBSC RIPTI 6562385010///ROC/PHNTR0225355 /1 FX USD 5115.60 AT 1.2492210 529004653/TMS/2026-04-28T01:17:03 GMT/MID/1.274802

Sheet EMEA APRIL 2026
A1: Date | B1: Amount Remaining | C1: Number | D1: Customer Name | E1: AR Specialist | F1: Memo
A2: 46128 | B2: 5330.002 | C2: PMT-S109-55181 | D2: VDI Technologiezentrum GmbH | E2: Theresa Saal | F2: 0402641043 1480429017260416 /ORD.CUST/VDI TECHNOLOGIEZENTRUM GMBH/EREF/0402641043/PAY.DET./IN S109-449170+
A3: 46134 | B3: 4174.937 | C3: PMT-S109-55252 | D3: Newspress Spain SL | E3: Nathalie Darmois | F3: NONREF 1480524653260422 /ORD.CUST/NEWSPRESS SPAIN,S.L./PAY.DET./IN-S109-449013
A4: 46135 | B4: 3526.851 | C4: PMT-S109-55263 | D4: Stadtkrankenhaus Delmenhorst GmbH | E4: Theresa Saal | F4: NONREF DE26042392928652 /ORD.CUST/DERDENGELDEN CMC WORLDWI/PAY.DET./IN-S109-448037/352110
A5: 46134 | B5: 3157.515 | C5: PMT-S109-55250 | D5: QUOBLY | E5: Nathalie Darmois | F5: MELTWATER.IN-S10 1480524438260 422 /ORD.CUST/QUOBLY/EREF/MELTWATER.IN-S109-449006.0/PAY.DET./IN-S109 449006
A6: 46120 | B6: 1281.249 | C6: PMT-S109-55090 | D6: CONSEIL SUPERIEUR DU NOTARIAT | E6: Nathalie Darmois | F6: 20260403.D55.253 14802425242604 08 /ORD.CUST/CONSEIL SUPERIEUR DU NOTARIAT/EREF/20260403.D55.253.8/P AY.DET./A
A7: 46139 | B7: 809.552 | C7: PMT-S109-55285 | D7: Landesdirektion Sachsen | E7: Theresa Saal | F7: 8300397767 1480612737260427 /ORD.CUST/HAUPTKASSE DES FREISTAATES SACHSEN/EREF/8300397767/PAY. DET./RNR.IN-S109-449247 RD.01.04.2026 SO CIAL MEDIA M .. TORING 04/2026 MEHRJAHRESVERTRAG HTTP.//
A8: 46141 | B8: 262.857 | C8: PMT-S109-55316 | D8: Urban Technology GmbH | E8: Theresa Saal | F8: NONREF DE26042993041090 /ORD.CUST/URBAN TECHNOLOGY GMBH/PAY.DET./IN-S109-445806 PAYMENT P LAN
A9: 46142 | B9: 7152.393 | C9: PMT-S104-51044 | D9: AFRODAD (African Forum & Network on Debt Development) | E9: Georgia Albutt-392 | F9: /REMI//URI/AFRODAD MELTWATER IN- S104-435161///ROC/OT26117ZW014101 7 S06611922E2601 /INS/SBZAZAJJ/OCMT/USD7290,00//BENM/GB84HBUK4011 6031212125 Meltwater (UK) Limited/EXCH/1.3762573//ORDP/AFRODAD 91 40000882177 31 ATKINSON DRIVE HILLSIDE/OBK/SBICZWHXXXX STANBIC BA NK ZIMBABWE LIMITED OTTOMAN HOUSE 59 SAMORA MACHEL AVENUE H/TMS/2 026-04-30T05:12:48 GMT/MID/1.34655650
A10: 46114 | B10: 1382.376 | C10: PMT-S104-50722 | D10: DUMMY CUSTOMER_CASHAPPS 321 - UK | E10: Amy Tyler | F10: /REMI/BEING PAYMENT FOR 2026 HOO TSUITE SUBSCRIPTION S0660923A0EF0 1/OCMT/USD1385,00//BENM/GB84HBUK40116031212125 Meltwater (UK) Lim ited/EXCH/1.3528468//ORDP/ECOBANK ZAMBIA LTD 154000204 22768 ACAC IA PARK THABO MBEKI ROAD P.O. B/OBK/ECOCZMLUXXX ECOBANK ZAMBIA LI MITED THABO MBEKI ROAD LUSAKA/TMS/2026-04-02T16:16:10 GMT/MID/1.3 2365590
A11: 46120 | B11: 675.14 | C11: PMT-S104-50747 | D11: MND Scotland | E11: Amy Tyler | F11: MND Scotland FP637B1734888997 /DbAcct/80071500767080 /ROC/S104-440219 /FPID/3000000017492138091020260408826800715
A12: 46135 | B12: 5551.375 | C12: PMT-S114-7017 | D12: Mood Design Trading Company (Single Person LLC) | F12: M0D FOR DESING AND COOOERCIAL COMPA /REF/OPERATIONAL EXPENSES PAYMENT O F INVOICE408110MOOD
A13: 46141 | B13: 4584.865 | C13: PMT-S114-7034 | D13: Fann Atheer LilDhi'ayah wal-I'lan (INVENU) | E13: Manar Sultan | F13: 1/INVENU COMPANY LAST PAYMENT FOR MELTWATER SETTLEME NT OF BILL FX USD 30956.00 AT 3.6530000 219244593 /TMS/2026-04-29T04:17:27 GMT/MID/3.6731200
A14: 46127 | B14: 368.035 | C14: PMT-S114-6999 | D14: Alizz Islamic Bank SAOC | E14: Manar Sultan | F14: ALIZZ ISLAMIC BANK VENDOR PAYMENT IN-S114-408098 FX USD 3700.00 AT 3.6530000 218592617/TMS/2026-04-15T12:18:30 GMT/MID/3.6731200
A15: 46128 | B15: 407.657 | C15: PMT-S144-11906 | D15: DUMMY CUSTOMER_CASHAPPS 391 - South Africa | E15: Jan Sutherland | F15: PAYMASTER PEOPLE SOLUTIONS PTY
A16: 46136 | B16: 5154.702 | C16: PMT-S117-13150 | D16: DUMMY CUSTOMER_CASHAPPS 401 - India | E16: Prabhat Aggarwal | F16: /00060330006652 LOTTEINDIACORPORATIONPRIVATELTD 2026/04/24 183004 HDFC042450066005 HDFCR52026042450066005
A17: 46122 | B17: 13008.558 | C17: PMT-S146-28090 | D17: Aktiebolaget Stockholms Spårvägar | E17: Max Hugo Larsson Ras Vidal | F17: STOCKHOLMS SPÅRVÄGAR AB
A18: 46134 | B18: 3692.742 | C18: PMT-S127-14174 | D18: Epax Norway AS | E18: Katarina Andersson | F18: 6535 079740586535 34500.00 34500.00 IBS 34500.00 EPAX NORWAY AS 5805 NO POSTBOKS 444 5805 BERGEN 15039928652 BBAN Meltwater News AS 0158 NO Nedre Vollgate 3 0158 OSLO 50100542177 BBAN CINV IN -S127-414250 34500.00 2026-04-22T00:00:00+02:00 2026-04-22 1 Overføring innland E86535
A19: 46142 | B19: 2781.598 | C19: PMT-S127-14184 | D19: EB MARINE AS | E19: Katarina Andersson | F19: 613 25987.50 EB MARINE AS MIDTG$RDVEIEN 16 4031 60750573188 BBAN 50100542177 BBAN EB MARINE AS 2026-04-30 2 Overføring innland 66761127059
